Workbook

Sheet Raport EEE
A1: Raport EEE - Ale Green
A2: Generat la: 01.09.2026, 06:49
A4: Filtre aplicate:
A5: Client: | B5: Toți clienții
A6: Grupă: | B6: Toate grupele
A7: Subgrupă: | B7: Toate subgrupele
A9: Totaluri:
A10: Total Bucăți: | B10: 1989387 | C10: Total Greutate (kg): | D10: 18014000 | E10: Valoare Totală (RON): | F10: 16869558
A12: Perioada | B12: Client | C12: CUI | D12: Cod Categorie | E12: Categorie | F12: Cod Subcategorie | G12: Subcategorie | H12: Bucăți | I12: Greutate (kg) | J12: Valoare (RON)
A13: Iulie 2026 | B13: CATE-N LUNA SI-N STELE SRL | C13: 39679960 | D13: 5 | E13: ECHIPAMENTE DE MICI DIMENSIUNI | F13: 5.5 | G13: Alte echipamente mici ≤ 0.2 kg | H13: 140 | I13: 0 | J13: 14
A14: Iulie 2026 | B14: CATE-N LUNA SI-N STELE SRL | C14: 39679960 | D14: 5 | E14: ECHIPAMENTE DE MICI DIMENSIUNI | F14: 5.6 | G14: Alte echipamente mici >0.2 kg ≤ 1 kg | H14: 296 | I14: 0 | J14: 88.8
A15: Iulie 2026 | B15: CATE-N LUNA SI-N STELE SRL | C15: 39679960 | D15: 5 | E15: ECHIPAMENTE DE MICI DIMENSIUNI | F15: 5.8 | G15: Alte echipamente mici > 2 kg ≤ 4 kg | H15: 23 | I15: 0 | J15: 59.8
A16: Iulie 2026 | B16: CATE-N LUNA SI-N STELE SRL | C16: 39679960 | D16: 5 | E16: ECHIPAMENTE DE MICI DIMENSIUNI | F16: 5.9 | G16: Alte echipamente mici > 4 kg ≤ 20 kg | H16: 4 | I16: 0 | J16: 26
A17: Iulie 2026 | B17: CATE-N LUNA SI-N STELE SRL | C17: 39679960 | D17: 3 | E17: LAMPI | F17: 3.1 | G17: Lampi LED | H17: 13 | I17: 0 | J17: 4.55
A18: Iulie 2026 | B18: SC SPOT VISION LIGHTING DISTRIBUTION SRL | C18: RO17072311 | D18: 3 | E18: LAMPI | F18: 3.1 | G18: Lampi LED | H18: 1765 | I18: 17.65 | J18: 617.75
A19: Iulie 2026 | B19: SC SPOT VISION LIGHTING DISTRIBUTION SRL | C19: RO17072311 | D19: 3 | E19: LAMPI | F19: 3.2 | G19: Alte lampi | H19: 189 | I19: 56.7 | J19: 132.3
A20: Iulie 2026 | B20: NOVO BRANDS SRL | C20: 42892720 | D20: 2 | E20: ECRANE, MONITOARE SI ECHIPAMENTE CU ECRANE | F20: 2.2 | G20: Calculatoare portabile | H20: 163 | I20: 310 | J20: 407.5
A21: Iulie 2026 | B21: Elbi Electric & Lighting SRL | C21: RO17412685 | D21: 5 | E21: ECHIPAMENTE DE MICI DIMENSIUNI | F21: 5.5 | G21: Alte echipamente mici ≤ 0.2 kg | H21: 218880 | I21: 12449.44 | J21: 21888
A22: Iulie 2026 | B22: Elbi Electric & Lighting SRL | C22: RO17412685 | D22: 5 | E22: ECHIPAMENTE DE MICI DIMENSIUNI | F22: 5.6 | G22: Alte echipamente mici >0.2 kg ≤ 1 kg | H22: 45498 | I22: 21619.32 | J22: 13649.4
A23: Iulie 2026 | B23: Elbi Electric & Lighting SRL | C23: RO17412685 | D23: 5 | E23: ECHIPAMENTE DE MICI DIMENSIUNI | F23: 5.7 | G23: Alte echipamente mici > 1kg ≤ 2 kg | H23: 7178 | I23: 10014.59 | J23: 9331.4
A24: Iulie 2026 | B24: Elbi Electric & Lighting SRL | C24: RO17412685 | D24: 5 | E24: ECHIPAMENTE DE MICI DIMENSIUNI | F24: 5.8 | G24: Alte echipamente mici > 2 kg ≤ 4 kg | H24: 2590 | I24: 6803.15 | J24: 6734
... A148: Februarie 2026 | B148: CATE-N LUNA SI-N STELE SRL | C148: 39679960 | D148: 5 | E148: ECHIPAMENTE DE MICI DIMENSIUNI | F148: 5.6 | G148: Alte echipamente mici >0.2 kg ≤ 1 kg | H148: 190 | I148: 123 | J148: 28.5
G149: TOTAL: | H149: 1989387 | I149: 18014000 | J149: 16869558

Sheet Procente
A1: Analiză procentuală – Raport EEE Ale Green
A3: Total greutate (kg): | B3: =SUM('Raport EEE'!$I$13:$I$148) -> 18014000
A5: 1. Ponderea fiecărui client din total greutate
A6: Client | B6: Greutate (kg) | C6: % din total
A7: ATLANTIS R.PW | B7: =SUMIF('Raport EEE'!$B$13:$B$148,$A7,'Raport EEE'!$I$13:$I$148) -> 3940298 | C7: =IF($B$3=0,0,B7/$B$3) -> 0.21873532
A8: BEKO ROMANIA S.A. | B8: =SUMIF('Raport EEE'!$B$13:$B$148,$A8,'Raport EEE'!$I$13:$I$148) -> 1566730.3 | C8: =IF($B$3=0,0,B8/$B$3) -> 0.086972924
A9: CATE-N LUNA SI-N STELE SRL | B9: =SUMIF('Raport EEE'!$B$13:$B$148,$A9,'Raport EEE'!$I$13:$I$148) -> 673 | C9: =IF($B$3=0,0,B9/$B$3) -> 3.7359831e-05
A10: Coral Business Instal SRL | B10: =SUMIF('Raport EEE'!$B$13:$B$148,$A10,'Raport EEE'!$I$13:$I$148) -> 364.34 | C10: =IF($B$3=0,0,B10/$B$3) -> 2.022538e-05
A11: ECO SUN NICULESTI S.R.L. | B11: =SUMIF('Raport EEE'!$B$13:$B$148,$A11,'Raport EEE'!$I$13:$I$148) -> 10787400 | C11: =IF($B$3=0,0,B11/$B$3) -> 0.59883424
A12: Elbi Electric & Lighting SRL | B12: =SUMIF('Raport EEE'!$B$13:$B$148,$A12,'Raport EEE'!$I$13:$I$148) -> 285326.77 | C12: =IF($B$3=0,0,B12/$B$3) -> 0.015839168
A13: Exemplu | B13: =SUMIF('Raport EEE'!$B$13:$B$148,$A13,'Raport EEE'!$I$13:$I$148) -> 36 | C13: =IF($B$3=0,0,B13/$B$3) -> 1.9984456e-06
A14: IHUNT TECHNOLOGY IMPORT-EXPORT S.A | B14: =SUMIF('Raport EEE'!$B$13:$B$148,$A14,'Raport EEE'!$I$13:$I$148) -> 32988 | C14: =IF($B$3=0,0,B14/$B$3) -> 0.0018312424
A15: NOVO BRANDS SRL | B15: =SUMIF('Raport EEE'!$B$13:$B$148,$A15,'Raport EEE'!$I$13:$I$148) -> 1049.73 | C15: =IF($B$3=0,0,B15/$B$3) -> 5.827301e-05
A16: OMAC SRL | B16: =SUMIF('Raport EEE'!$B$13:$B$148,$A16,'Raport EEE'!$I$13:$I$148) -> 56324.6 | C16: =IF($B$3=0,0,B16/$B$3) -> 0.0031267125
A17: Paragon Electroinvest SRL | B17: =SUMIF('Raport EEE'!$B$13:$B$148,$A17,'Raport EEE'!$I$13:$I$148) -> 27242.861 | C17: =IF($B$3=0,0,B17/$B$3) -> 0.001512316
A18: RIA DO TRADING SRL | B18: =SUMIF('Raport EEE'!$B$13:$B$148,$A18,'Raport EEE'!$I$13:$I$148) -> 4533.3 | C18: =IF($B$3=0,0,B18/$B$3) -> 0.00025165427
... A20: SC SPOT VISION LIGHTING DISTRIBUTION SRL | B20: =SUMIF('Raport EEE'!$B$13:$B$148,$A20,'Raport EEE'!$I$13:$I$148) -> 239.23 | C20: =IF($B$3=0,0,B20/$B$3) -> 1.3280226e-05
A21: TOTAL | B21: =SUM(B7:B20) -> 18014000 | C21: =SUM(C7:C20) -> 1
A24: 2. Ponderea fiecărei categorii din total greutate
A25: Categorie | B25: Greutate (kg) | C25: % din total | D25: Cod
A26: ECRANE, MONITOARE SI ECHIPAMENTE CU ECRANE CATEGORIA 2 | B26: 977.73 | C26: =IF($B$3=0,0,B26/$B$3) -> 5.4276118e-05 | D26: 2
A27: LAMPI CATEGORIA 3 | B27: 301.82 | C27: =IF($B$3=0,0,B27/$B$3) -> 1.6754746e-05 | D27: 3
A28: ECHIPAMENTE DE MARI DIMENSIUNI CATEGORIA 4 | B28: 1620533.5 | C28: =IF($B$3=0,0,B28/$B$3) -> 0.089959669 | D28: 4
A29: PANOURI FOTOVOLTAICE CATEGORIA 4B | B29: 16040907 | C29: =IF($B$3=0,0,B29/$B$3) -> 0.89046891 | D29: 4B
A30: ECHIPAMENTE DE MICI DIMENSIUNI CATEGORIA 5 | B30: 342940.56 | C30: =IF($B$3=0,0,B30/$B$3) -> 0.019037446 | D30: 5
A31: ECHIP. IT&C MICI CATEGORIA 6 | B31: 8339.5 | C31: =IF($B$3=0,0,B31/$B$3) -> 0.00046294548 | D31: 6
A32: TOTAL | B32: =SUM(B26:B31) -> 18014000 | C32: =SUM(C26:C31) -> 1
A35: 3. Ponderea fiecărui client în cadrul fiecărei categorii (% din total categorie)
A36: Categorie | B36: Client | C36: Greutate (kg) | D36: % din categorie | E36: % din total general
A37: ECRANE, MONITOARE SI ECHIPAMENTE CU ECRANE | B37: NOVO BRANDS SRL | C37: =SUMIFS('Raport EEE'!$I$13:$I$148,'Raport EEE'!$E$13:$E$148,$A37,'Raport EEE'!$B$13:$B$148,$B37) -> 977.73 | D37: =IF($B$26=0,0,C37/$B$26) -> 1 | E37: =IF($B$3=0,0,C37/$B$3) -> 5.4276118e-05
A38: Subtotal | B38: ECRANE, MONITOARE SI ECHIPAMENTE CU ECRANE | C38: =SUM(C37:C37) -> 977.73 | D38: =SUM(D37:D37) -> 1 | E38: =SUM(E37:E37) -> 5.4276118e-05
A40: LAMPI | B40: SC SPOT VISION LIGHTING DISTRIBUTION SRL | C40: =SUMIFS('Raport EEE'!$I$13:$I$148,'Raport EEE'!$E$13:$E$148,$A40,'Raport EEE'!$B$13:$B$148,$B40) -> 239.23 | D40: =IF($B$27=0,0,C40/$B$27) -> 0.79262474 | E40: =IF($B$3=0,0,C40/$B$3) -> 1.3280226e-05
A41: LAMPI | B41: CATE-N LUNA SI-N STELE SRL | C41: =SUMIFS('Raport EEE'!$I$13:$I$148,'Raport EEE'!$E$13:$E$148,$A41,'Raport EEE'!$B$13:$B$148,$B41) -> 35 | D41: =IF($B$27=0,0,C41/$B$27) -> 0.11596316 | E41: =IF($B$3=0,0,C41/$B$3) -> 1.9429333e-06
A42: LAMPI | B42: Paragon Electroinvest SRL | C42: =SUMIFS('Raport EEE'!$I$13:$I$148,'Raport EEE'!$E$13:$E$148,$A42,'Raport EEE'!$B$13:$B$148,$B42) -> 27.59 | D42: =IF($B$27=0,0,C42/$B$27) -> 0.0914121 | E42: =IF($B$3=0,0,C42/$B$3) -> 1.5315865e-06
A43: Subtotal | B43: LAMPI | C43: =SUM(C40:C42) -> 301.82 | D43: =SUM(D40:D42) -> 1 | E43: =SUM(E40:E42) -> 1.6754746e-05
A45: ECHIPAMENTE DE MARI DIMENSIUNI | B45: BEKO ROMANIA S.A. | C45: =SUMIFS('Raport EEE'!$I$13:$I$148,'Raport EEE'!$E$13:$E$148,$A45,'Raport EEE'!$B$13:$B$148,$B45) -> 1537289.2 | D45: =IF($B$28=0,0,C45/$B$28) -> 0.94863155 | E45: =IF($B$3=0,0,C45/$B$3) -> 0.08533858
A46: ECHIPAMENTE DE MARI DIMENSIUNI | B46: OMAC SRL | C46: =SUMIFS('Raport EEE'!$I$13:$I$148,'Raport EEE'!$E$13:$E$148,$A46,'Raport EEE'!$B$13:$B$148,$B46) -> 56324.6 | D46: =IF($B$28=0,0,C46/$B$28) -> 0.034756826 | E46: =IF($B$3=0,0,C46/$B$3) -> 0.0031267125
A47: ECHIPAMENTE DE MARI DIMENSIUNI | B47: ATLANTIS R.PW | C47: =SUMIFS('Raport EEE'!$I$13:$I$148,'Raport EEE'!$E$13:$E$148,$A47,'Raport EEE'!$B$13:$B$148,$B47) -> 15776 | D47: =IF($B$28=0,0,C47/$B$28) -> 0.0097350657 | E47: =IF($B$3=0,0,C47/$B$3) -> 0.00087576329
A48: ECHIPAMENTE DE MARI DIMENSIUNI | B48: RO.IPP1 S.R.L | C48: =SUMIFS('Raport EEE'!$I$13:$I$148,'Raport EEE'!$E$13:$E$148,$A48,'Raport EEE'!$B$13:$B$148,$B48) -> 6136 | D48: =IF($B$28=0,0,C48/$B$28) -> 0.0037864074 | E48: =IF($B$3=0,0,C48/$B$3) -> 0.00034062396
A49: ECHIPAMENTE DE MARI DIMENSIUNI | B49: RIA DO TRADING SRL | C49: =SUMIFS('Raport EEE'!$I$13:$I$148,'Raport EEE'!$E$13:$E$148,$A49,'Raport EEE'!$B$13:$B$148,$B49) -> 3971 | D49: =IF($B$28=0,0,C49/$B$28) -> 0.0024504276 | E49: =IF($B$3=0,0,C49/$B$3) -> 0.00022043966
...

Sheet Colectat
B1: COLECTAT IULIE KG | C1: COLECTAT AUGUST KG
A2: ECRANE, MONITOARE SI ECHIPAMENTE CU ECRANE | B2: 30 | C2: 10
A3: LAMPI | B3: 50 | C3: 20
A4: ECHIPAMENTE DE MARI DIMENSIUNI | B4: 1200000 | C4: 200000
A5: PANOURI FOTOVOLTAICE | B5: 2000000 | C5: 300000
A6: ECHIPAMENTE DE MICI DIMENSIUNI | B6: 130000 | C6: 50000
A7: ECHIP. IT&C MICI | B7: 1300 | C7: 500

Sheet Alocare colectat
A1: Alocarea cantităților colectate (iulie + august) pe clienți
A2: Reguli: obligația = 21,67% din declarat · cat. 3 (Lămpi) se îndeplinește 100% doar cu lămpi colectate · cat. 2, 4, 5, 6 – minim 30% din obligație cu colectat din categoria proprie, restul de 70% cu orice categorie · panourile (4B) – integral din orice categorie.
A3: Rata de colectare (obligație din declarat): | C3: 0.2167 | D3: ← celulă de intrare
A4: Minim din categoria proprie (din obligație): | C4: 0.3 | D4: ← celulă de intrare
A5: Pool disponibil pentru realocare (kg): | C5: =SUM(J10:J15) -> 1154519.8
A6: din care colectat în iulie (kg): | C6: =SUM(U10:U15) -> 975328.66
A7: cota de iulie în pool: | C7: =IF($C$5=0,0,$C$6/$C$5) -> 0.84479165
A9: Cod | B9: Categorie | C9: Declarat (kg) | D9: Obligație 21,67% (kg) | E9: Minim obligatoriu din categoria proprie (kg) | F9: Colectat iulie (kg) | G9: Colectat august (kg) | H9: Colectat total (kg) | I9: Utilizat din propriu (kg) | J9: Surplus în pool (kg) | K9: Necesar rămas (kg) | L9: Maxim admis din alte categorii (kg) | M9: Alocat din pool (kg) | N9: Pool rămas (kg) | O9: TOTAL alocat (kg) | P9: % din obligație | Q9: Alocat iulie (kg) | R9: Alocat august (kg) | S9: Regulă aplicată | T9: Utilizat propriu – iulie | U9: Surplus în pool – iulie
A10: 2 | B10: ECRANE, MONITOARE SI ECHIPAMENTE CU ECRANE | C10: =SUMIF('Raport EEE'!$E$13:$E$148,$B10,'Raport EEE'!$I$13:$I$148) -> 977.73 | D10: =C10*$C$3 -> 211.87409 | E10: =D10*$C$4 -> 63.562227 | F10: =IFERROR(INDEX(Colectat!$B$2:$B$7,MATCH($B10,Colectat!$A$2:$A$7,0)),0) -> 30 | G10: =IFERROR(INDEX(Colectat!$C$2:$C$7,MATCH($B10,Colectat!$A$2:$A$7,0)),0) -> 10 | H10: =F10+G10 -> 40 | I10: =MIN(H10,D10) -> 40 | J10: =H10-I10 -> 0 | K10: =D10-I10 -> 171.87409 | L10: =MIN(K10,D10*(1-$C$4)) -> 148.31186 | M10: =MIN(L10,$C$5) -> 148.31186 | N10: =$C$5-M10 -> 1154371.5 | O10: =I10+M10 -> 188.31186 | P10: =IF(D10=0,0,O10/D10) -> 0.88879137 | Q10: =T10+M10*$C$7 -> 155.29262 | R10: =O10-Q10 -> 33.01924 | S10: Min. 30% din obligație cu propriu; max 70% din alte categorii | T10: =IF(H10=0,0,I10*F10/H10) -> 30 | U10: =IF(H10=0,0,J10*F10/H10) -> 0
A11: 3 | B11: LAMPI | C11: =SUMIF('Raport EEE'!$E$13:$E$148,$B11,'Raport EEE'!$I$13:$I$148) -> 301.82 | D11: =C11*$C$3 -> 65.404394 | E11: =D11 -> 65.404394 | F11: =IFERROR(INDEX(Colectat!$B$2:$B$7,MATCH($B11,Colectat!$A$2:$A$7,0)),0) -> 50 | G11: =IFERROR(INDEX(Colectat!$C$2:$C$7,MATCH($B11,Colectat!$A$2:$A$7,0)),0) -> 20 | H11: =F11+G11 -> 70 | I11: =MIN(H11,D11) -> 65.404394 | J11: =H11-I11 -> 4.595606 | K11: =D11-I11 -> 0 | L11: 0 | M11: =MIN(L11,N10) -> 0 | N11: =N10-M11 -> 1154371.5 | O11: =I11+M11 -> 65.404394 | P11: =IF(D11=0,0,O11/D11) -> 1 | Q11: =T11+M11*$C$7 -> 46.717424 | R11: =O11-Q11 -> 18.68697 | S11: Doar categoria proprie (100% lămpi) | T11: =IF(H11=0,0,I11*F11/H11) -> 46.717424 | U11: =IF(H11=0,0,J11*F11/H11) -> 3.2825757
A12: 4 | B12: ECHIPAMENTE DE MARI DIMENSIUNI | C12: =SUMIF('Raport EEE'!$E$13:$E$148,$B12,'Raport EEE'!$I$13:$I$148) -> 1620533.5 | D12: =C12*$C$3 -> 351169.61 | E12: =D12*$C$4 -> 105350.88 | F12: =IFERROR(INDEX(Colectat!$B$2:$B$7,MATCH($B12,Colectat!$A$2:$A$7,0)),0) -> 1200000 | G12: =IFERROR(INDEX(Colectat!$C$2:$C$7,MATCH($B12,Colectat!$A$2:$A$7,0)),0) -> 200000 | H12: =F12+G12 -> 1400000 | I12: =MIN(H12,D12) -> 351169.61 | J12: =H12-I12 -> 1048830.4 | K12: =D12-I12 -> 0 | L12: =MIN(K12,D12*(1-$C$4)) -> 0 | M12: =MIN(L12,N11) -> 0 | N12: =N11-M12 -> 1154371.5 | O12: =I12+M12 -> 351169.61 | P12: =IF(D12=0,0,O12/D12) -> 1 | Q12: =T12+M12*$C$7 -> 301002.52 | R12: =O12-Q12 -> 50167.087 | S12: Min. 30% din obligație cu propriu; max 70% din alte categorii | T12: =IF(H12=0,0,I12*F12/H12) -> 301002.52 | U12: =IF(H12=0,0,J12*F12/H12) -> 898997.48
A13: 5 | B13: ECHIPAMENTE DE MICI DIMENSIUNI | C13: =SUMIF('Raport EEE'!$E$13:$E$148,$B13,'Raport EEE'!$I$13:$I$148) -> 342940.56 | D13: =C13*$C$3 -> 74315.22 | E13: =D13*$C$4 -> 22294.566 | F13: =IFERROR(INDEX(Colectat!$B$2:$B$7,MATCH($B13,Colectat!$A$2:$A$7,0)),0) -> 130000 | G13: =IFERROR(INDEX(Colectat!$C$2:$C$7,MATCH($B13,Colectat!$A$2:$A$7,0)),0) -> 50000 | H13: =F13+G13 -> 180000 | I13: =MIN(H13,D13) -> 74315.22 | J13: =H13-I13 -> 105684.78 | K13: =D13-I13 -> 0 | L13: =MIN(K13,D13*(1-$C$4)) -> 0 | M13: =MIN(L13,N12) -> 0 | N13: =N12-M13 -> 1154371.5 | O13: =I13+M13 -> 74315.22 | P13: =IF(D13=0,0,O13/D13) -> 1 | Q13: =T13+M13*$C$7 -> 53672.103 | R13: =O13-Q13 -> 20643.117 | S13: Min. 30% din obligație cu propriu; max 70% din alte categorii | T13: =IF(H13=0,0,I13*F13/H13) -> 53672.103 | U13: =IF(H13=0,0,J13*F13/H13) -> 76327.897
A14: 6 | B14: ECHIP. IT&C MICI | C14: =SUMIF('Raport EEE'!$E$13:$E$148,$B14,'Raport EEE'!$I$13:$I$148) -> 8339.5 | D14: =C14*$C$3 -> 1807.1697 | E14: =D14*$C$4 -> 542.15089 | F14: =IFERROR(INDEX(Colectat!$B$2:$B$7,MATCH($B14,Colectat!$A$2:$A$7,0)),0) -> 1300 | G14: =IFERROR(INDEX(Colectat!$C$2:$C$7,MATCH($B14,Colectat!$A$2:$A$7,0)),0) -> 500 | H14: =F14+G14 -> 1800 | I14: =MIN(H14,D14) -> 1800 | J14: =H14-I14 -> 0 | K14: =D14-I14 -> 7.16965 | L14: =MIN(K14,D14*(1-$C$4)) -> 7.16965 | M14: =MIN(L14,N13) -> 7.16965 | N14: =N13-M14 -> 1154364.3 | O14: =I14+M14 -> 1807.1697 | P14: =IF(D14=0,0,O14/D14) -> 1 | Q14: =T14+M14*$C$7 -> 1306.0569 | R14: =O14-Q14 -> 501.11279 | S14: Min. 30% din obligație cu propriu; max 70% din alte categorii | T14: =IF(H14=0,0,I14*F14/H14) -> 1300 | U14: =IF(H14=0,0,J14*F14/H14) -> 0
A15: 4B | B15: PANOURI FOTOVOLTAICE | C15: =SUMIF('Raport EEE'!$E$13:$E$148,$B15,'Raport EEE'!$I$13:$I$148) -> 16040907 | D15: =C15*$C$3 -> 3476064.5 | E15: 0 | F15: =IFERROR(INDEX(Colectat!$B$2:$B$7,MATCH($B15,Colectat!$A$2:$A$7,0)),0) -> 2000000 | G15: =IFERROR(INDEX(Colectat!$C$2:$C$7,MATCH($B15,Colectat!$A$2:$A$7,0)),0) -> 300000 | H15: =F15+G15 -> 2300000 | I15: =MIN(H15,D15) -> 2300000 | J15: =H15-I15 -> 0 | K15: =D15-I15 -> 1176064.5 | L15: =K15 -> 1176064.5 | M15: =MIN(L15,N14) -> 1154364.3 | N15: =N14-M15 -> 0 | O15: =I15+M15 -> 3454364.3 | P15: =IF(D15=0,0,O15/D15) -> 0.99375723 | Q15: =T15+M15*$C$7 -> 2975197.3 | R15: =O15-Q15 -> 479166.98 | S15: Integral din orice categorie colectată | T15: =IF(H15=0,0,I15*F15/H15) -> 2000000 | U15: =IF(H15=0,0,J15*F15/H15) -> 0
B16: TOTAL | C16: =SUM(C10:C15) -> 18014000 | D16: =SUM(D10:D15) -> 3903633.8 | E16: =SUM(E10:E15) -> 128316.57 | F16: =SUM(F10:F15) -> 3331380 | G16: =SUM(G10:G15) -> 550530 | H16: =SUM(H10:H15) -> 3881910 | I16: =SUM(I10:I15) -> 2727390.2 | J16: =SUM(J10:J15) -> 1154519.8 | K16: =SUM(K10:K15) -> 1176243.6 | M16: =SUM(M10:M15) -> 1154519.8 | O16: =SUM(O10:O15) -> 3881910 | P16: =IF(D16=0,0,O16/D16) -> 0.99443497 | Q16: =SUM(Q10:Q15) -> 3331380 | R16: =SUM(R10:R15) -> 550530
A18: Verificare – total alocat vs. colectat disponibil (kg): | C18: =O16-H16 -> 0 | D18: =IF(ABS(C18)<0.01,"OK – tot colectatul este alocat","Diferență = colectat rămas nealocat") -> OK – tot colectatul este alocat
A19: Colectat rămas nealocat (pool neutilizat, kg): | C19: =N15 -> 0
A20: Verificare alocat iulie + august = total alocat (kg): | C20: =Q16+R16-O16 -> 0
A23: Alocarea pe clienți – proporțional cu ponderea fiecărui client în categorie
A24: Cod | B24: Categorie | C24: Client | D24: Declarat (kg) | E24: Obligație 21,67% (kg) | F24: % din categorie | G24: Alocat TOTAL (kg) | H24: Alocat iulie (kg) | I24: Alocat august (kg) | J24: % îndeplinire
A25: 2 | B25: ECRANE, MONITOARE SI ECHIPAMENTE CU ECRANE | C25: NOVO BRANDS SRL | D25: =SUMIFS('Raport EEE'!$I$13:$I$148,'Raport EEE'!$E$13:$E$148,$B25,'Raport EEE'!$B$13:$B$148,$C25) -> 977.73 | E25: =D25*$C$3 -> 211.87409 | F25: =IF($C$10=0,0,D25/$C$10) -> 1 | G25: =F25*$O$10 -> 188.31186 | H25: =F25*$Q$10 -> 155.29262 | I25: =F25*$R$10 -> 33.01924 | J25: =IF(E25=0,0,G25/E25) -> 0.88879137
B26: Subtotal | C26: ECRANE, MONITOARE SI ECHIPAMENTE CU ECRANE | D26: =SUM(D25:D25) -> 977.73 | E26: =SUM(E25:E25) -> 211.87409 | F26: =SUM(F25:F25) -> 1 | G26: =SUM(G25:G25) -> 188.31186 | H26: =SUM(H25:H25) -> 155.29262 | I26: =SUM(I25:I25) -> 33.01924 | J26: =IF(E26=0,0,G26/E26) -> 0.88879137
A28: 3 | B28: LAMPI | C28: SC SPOT VISION LIGHTING DISTRIBUTION SRL | D28: =SUMIFS('Raport EEE'!$I$13:$I$148,'Raport EEE'!$E$13:$E$148,$B28,'Raport EEE'!$B$13:$B$148,$C28) -> 239.23 | E28: =D28*$C$3 -> 51.841141 | F28: =IF($C$11=0,0,D28/$C$11) -> 0.79262474 | G28: =F28*$O$11 -> 51.841141 | H28: =F28*$Q$11 -> 37.029386 | I28: =F28*$R$11 -> 14.811755 | J28: =IF(E28=0,0,G28/E28) -> 1
A29: 3 | B29: LAMPI | C29: CATE-N LUNA SI-N STELE SRL | D29: =SUMIFS('Raport EEE'!$I$13:$I$148,'Raport EEE'!$E$13:$E$148,$B29,'Raport EEE'!$B$13:$B$148,$C29) -> 35 | E29: =D29*$C$3 -> 7.5845 | F29: =IF($C$11=0,0,D29/$C$11) -> 0.11596316 | G29: =F29*$O$11 -> 7.5845 | H29: =F29*$Q$11 -> 5.4175 | I29: =F29*$R$11 -> 2.167 | J29: =IF(E29=0,0,G29/E29) -> 1
A30: 3 | B30: LAMPI | C30: Paragon Electroinvest SRL | D30: =SUMIFS('Raport EEE'!$I$13:$I$148,'Raport EEE'!$E$13:$E$148,$B30,'Raport EEE'!$B$13:$B$148,$C30) -> 27.59 | E30: =D30*$C$3 -> 5.978753 | F30: =IF($C$11=0,0,D30/$C$11) -> 0.0914121 | G30: =F30*$O$11 -> 5.978753 | H30: =F30*$Q$11 -> 4.2705379 | I30: =F30*$R$11 -> 1.7082151 | J30: =IF(E30=0,0,G30/E30) -> 1
B31: Subtotal | C31: LAMPI | D31: =SUM(D28:D30) -> 301.82 | E31: =SUM(E28:E30) -> 65.404394 | F31: =SUM(F28:F30) -> 1 | G31: =SUM(G28:G30) -> 65.404394 | H31: =SUM(H28:H30) -> 46.717424 | I31: =SUM(I28:I30) -> 18.68697 | J31: =IF(E31=0,0,G31/E31) -> 1
A33: 4 | B33: ECHIPAMENTE DE MARI DIMENSIUNI | C33: BEKO ROMANIA S.A. | D33: =SUMIFS('Raport EEE'!$I$13:$I$148,'Raport EEE'!$E$13:$E$148,$B33,'Raport EEE'!$B$13:$B$148,$C33) -> 1537289.2 | E33: =D33*$C$3 -> 333130.57 | F33: =IF($C$12=0,0,D33/$C$12) -> 0.94863155 | G33: =F33*$O$12 -> 333130.57 | H33: =F33*$Q$12 -> 285540.49 | I33: =F33*$R$12 -> 47590.081 | J33: =IF(E33=0,0,G33/E33) -> 1
A34: 4 | B34: ECHIPAMENTE DE MARI DIMENSIUNI | C34: OMAC SRL | D34: =SUMIFS('Raport EEE'!$I$13:$I$148,'Raport EEE'!$E$13:$E$148,$B34,'Raport EEE'!$B$13:$B$148,$C34) -> 56324.6 | E34: =D34*$C$3 -> 12205.541 | F34: =IF($C$12=0,0,D34/$C$12) -> 0.034756826 | G34: =F34*$O$12 -> 12205.541 | H34: =F34*$Q$12 -> 10461.892 | I34: =F34*$R$12 -> 1743.6487 | J34: =IF(E34=0,0,G34/E34) -> 1
A35: 4 | B35: ECHIPAMENTE DE MARI DIMENSIUNI | C35: ATLANTIS R.PW | D35: =SUMIFS('Raport EEE'!$I$13:$I$148,'Raport EEE'!$E$13:$E$148,$B35,'Raport EEE'!$B$13:$B$148,$C35) -> 15776 | E35: =D35*$C$3 -> 3418.6592 | F35: =IF($C$12=0,0,D35/$C$12) -> 0.0097350657 | G35: =F35*$O$12 -> 3418.6592 | H35: =F35*$Q$12 -> 2930.2793 | I35: =F35*$R$12 -> 488.37989 | J35: =IF(E35=0,0,G35/E35) -> 1
A36: 4 | B36: ECHIPAMENTE DE MARI DIMENSIUNI | C36: RO.IPP1 S.R.L | D36: =SUMIFS('Raport EEE'!$I$13:$I$148,'Raport EEE'!$E$13:$E$148,$B36,'Raport EEE'!$B$13:$B$148,$C36) -> 6136 | E36: =D36*$C$3 -> 1329.6712 | F36: =IF($C$12=0,0,D36/$C$12) -> 0.0037864074 | G36: =F36*$O$12 -> 1329.6712 | H36: =F36*$Q$12 -> 1139.7182 | I36: =F36*$R$12 -> 189.95303 | J36: =IF(E36=0,0,G36/E36) -> 1
A37: 4 | B37: ECHIPAMENTE DE MARI DIMENSIUNI | C37: RIA DO TRADING SRL | D37: =SUMIFS('Raport EEE'!$I$13:$I$148,'Raport EEE'!$E$13:$E$148,$B37,'Raport EEE'!$B$13:$B$148,$C37) -> 3971 | E37: =D37*$C$3 -> 860.5157 | F37: =IF($C$12=0,0,D37/$C$12) -> 0.0024504276 | G37: =F37*$O$12 -> 860.5157 | H37: =F37*$Q$12 -> 737.58489 | I37: =F37*$R$12 -> 122.93081 | J37: =IF(E37=0,0,G37/E37) -> 1
A38: 4 | B38: ECHIPAMENTE DE MARI DIMENSIUNI | C38: Paragon Electroinvest SRL | D38: =SUMIFS('Raport EEE'!$I$13:$I$148,'Raport EEE'!$E$13:$E$148,$B38,'Raport EEE'!$B$13:$B$148,$C38) -> 675 | E38: =D38*$C$3 -> 146.2725 | F38: =IF($C$12=0,0,D38/$C$12) -> 0.0004165295 | G38: =F38*$O$12 -> 146.2725 | H38: =F38*$Q$12 -> 125.37643 | I38: =F38*$R$12 -> 20.896071 | J38: =IF(E38=0,0,G38/E38) -> 1
A39: 4 | B39: ECHIPAMENTE DE MARI DIMENSIUNI | C39: Coral Business Instal SRL | D39: =SUMIFS('Raport EEE'!$I$13:$I$148,'Raport EEE'!$E$13:$E$148,$B39,'Raport EEE'!$B$13:$B$148,$C39) -> 253.7 | E39: =D39*$C$3 -> 54.97679 | F39: =IF($C$12=0,0,D39/$C$12) -> 0.00015655338 | G39: =F39*$O$12 -> 54.97679 | H39: =F39*$Q$12 -> 47.122963 | I39: =F39*$R$12 -> 7.8538271 | J39: =IF(E39=0,0,G39/E39) -> 1
A40: 4 | B40: ECHIPAMENTE DE MARI DIMENSIUNI | C40: NOVO BRANDS SRL | D40: =SUMIFS('Raport EEE'!$I$13:$I$148,'Raport EEE'!$E$13:$E$148,$B40,'Raport EEE'!$B$13:$B$148,$C40) -> 72 | E40: =D40*$C$3 -> 15.6024 | F40: =IF($C$12=0,0,D40/$C$12) -> 4.4429813e-05 | G40: =F40*$O$12 -> 15.6024 | H40: =F40*$Q$12 -> 13.373486 | I40: =F40*$R$12 -> 2.2289143 | J40: =IF(E40=0,0,G40/E40) -> 1
A41: 4 | B41: ECHIPAMENTE DE MARI DIMENSIUNI | C41: Exemplu | D41: =SUMIFS('Raport EEE'!$I$13:$I$148,'Raport EEE'!$E$13:$E$148,$B41,'Raport EEE'!$B$13:$B$148,$C41) -> 36 | E41: =D41*$C$3 -> 7.8012 | F41: =IF($C$12=0,0,D41/$C$12) -> 2.2214907e-05 | G41: =F41*$O$12 -> 7.8012 | H41: =F41*$Q$12 -> 6.6867429 | I41: =F41*$R$12 -> 1.1144571 | J41: =IF(E41=0,0,G41/E41) -> 1
B42: Subtotal | C42: ECHIPAMENTE DE MARI DIMENSIUNI | D42: =SUM(D33:D41) -> 1620533.5 | E42: =SUM(E33:E41) -> 351169.61 | F42: =SUM(F33:F41) -> 1 | G42: =SUM(G33:G41) -> 351169.61 | H42: =SUM(H33:H41) -> 301002.52 | I42: =SUM(I33:I41) -> 50167.087 | J42: =IF(E42=0,0,G42/E42) -> 1
A44: 5 | B44: ECHIPAMENTE DE MICI DIMENSIUNI | C44: Elbi Electric & Lighting SRL | D44: =SUMIFS('Raport EEE'!$I$13:$I$148,'Raport EEE'!$E$13:$E$148,$B44,'Raport EEE'!$B$13:$B$148,$C44) -> 285326.77 | E44: =D44*$C$3 -> 61830.311 | F44: =IF($C$13=0,0,D44/$C$13) -> 0.83200065 | G44: =F44*$O$13 -> 61830.311 | H44: =F44*$Q$13 -> 44655.225 | I44: =F44*$R$13 -> 17175.086 | J44: =IF(E44=0,0,G44/E44) -> 1
A45: 5 | B45: ECHIPAMENTE DE MICI DIMENSIUNI | C45: BEKO ROMANIA S.A. | D45: =SUMIFS('Raport EEE'!$I$13:$I$148,'Raport EEE'!$E$13:$E$148,$B45,'Raport EEE'!$B$13:$B$148,$C45) -> 29441.08 | E45: =D45*$C$3 -> 6379.882 | F45: =IF($C$13=0,0,D45/$C$13) -> 0.085848929 | G45: =F45*$O$13 -> 6379.882 | H45: =F45*$Q$13 -> 4607.6926 | I45: =F45*$R$13 -> 1772.1895 | J45: =IF(E45=0,0,G45/E45) -> 1
A46: 5 | B46: ECHIPAMENTE DE MICI DIMENSIUNI | C46: IHUNT TECHNOLOGY IMPORT-EXPORT S.A | D46: =SUMIFS('Raport EEE'!$I$13:$I$148,'Raport EEE'!$E$13:$E$148,$B46,'Raport EEE'!$B$13:$B$148,$C46) -> 24387.5 | E46: =D46*$C$3 -> 5284.7712 | F46: =IF($C$13=0,0,D46/$C$13) -> 0.071112906 | G46: =F46*$O$13 -> 5284.7712 | H46: =F46*$Q$13 -> 3816.7792 | I46: =F46*$R$13 -> 1467.992 | J46: =IF(E46=0,0,G46/E46) -> 1
A47: 5 | B47: ECHIPAMENTE DE MICI DIMENSIUNI | C47: Paragon Electroinvest SRL | D47: =SUMIFS('Raport EEE'!$I$13:$I$148,'Raport EEE'!$E$13:$E$148,$B47,'Raport EEE'!$B$13:$B$148,$C47) -> 2474.271 | E47: =D47*$C$3 -> 536.17453 | F47: =IF($C$13=0,0,D47/$C$13) -> 0.0072148684 | G47: =F47*$O$13 -> 536.17453 | H47: =F47*$Q$13 -> 387.23716 | I47: =F47*$R$13 -> 148.93737 | J47: =IF(E47=0,0,G47/E47) -> 1
...

Sheet Exemplu regulă
A1: Exemplu de verificare a regulii – client cu 100 kg declarate
A2: Celulele albastre sunt intrări; restul sunt formule.
A3: Rata de colectare: | C3: 0.2167
A4: Minim din categoria proprie (din obligație): | C4: 0.3
A6: Categorie | B6: Declarat (kg) | C6: Obligație 21,67% (kg) | D6: Minim din categoria proprie (kg) | E6: Poate fi din orice categorie (kg) | F6: Regulă
A7: LAMPI | B7: 20 | C7: =B7*$C$3 -> 4.334 | D7: =C7 -> 4.334 | E7: =C7-D7 -> 0 | F7: Doar lămpi colectate (100%)
A8: ECRANE, MONITOARE SI ECHIPAMENTE CU ECRANE | B8: 20 | C8: =B8*$C$3 -> 4.334 | D8: =C8*$C$4 -> 1.3002 | E8: =C8-D8 -> 3.0338 | F8: Min. 30% ecrane, restul orice categorie
A9: ECHIPAMENTE DE MARI DIMENSIUNI | B9: 40 | C9: =B9*$C$3 -> 8.668 | D9: =C9*$C$4 -> 2.6004 | E9: =C9-D9 -> 6.0676 | F9: Min. 30% echip. mari, restul orice categorie
A10: ECHIPAMENTE DE MICI DIMENSIUNI | B10: 10 | C10: =B10*$C$3 -> 2.167 | D10: =C10*$C$4 -> 0.6501 | E10: =C10-D10 -> 1.5169 | F10: Min. 30% echip. mici, restul orice categorie
A11: PANOURI FOTOVOLTAICE | B11: 10 | C11: =B11*$C$3 -> 2.167 | D11: 0 | E11: =C11-D11 -> 2.167 | F11: Integral din orice categorie
A12: TOTAL | B12: =SUM(B7:B11) -> 100 | C12: =SUM(C7:C11) -> 21.67 | D12: =SUM(D7:D11) -> 8.8847 | E12: =SUM(E7:E11) -> 12.7853
A14: Aceasta este exact logica aplicată în foaia „Alocare colectat" pe datele reale.
